Workbook

Sheet Summary
A1: Kose Web – Suffolk call list
A2: Businesses with no website on Google Maps (or only social / booking pages). Source: Google Maps (Places API), 16 Oct 2026, cleaned by Kose Web.
A4: Industry | B4: Leads | C4: Checked (Y) | D4: Already has website | E4: Called | F4: Interested / preview sent | G4: Won
A5: Food & drink | B5: =COUNTA('Food & drink'!B:B)-1 -> 300 | C5: =COUNTIF('Food & drink'!O:O,"Y") -> 0 | D5: =COUNTIF('Food & drink'!O:O,"N")+COUNTIF('Food & drink'!Q:Q,"Already has website") -> 0 | E5: =COUNT('Food & drink'!P:P) -> 0 | F5: =COUNTIF('Food & drink'!Q:Q,"Interested - send preview")+COUNTIF('Food & drink'!Q:Q,"Preview sent") -> 0 | G5: =COUNTIF('Food & drink'!Q:Q,"Won") -> 0
A6: Hair & barbers | B6: =COUNTA('Hair & barbers'!B:B)-1 -> 235 | C6: =COUNTIF('Hair & barbers'!O:O,"Y") -> 0 | D6: =COUNTIF('Hair & barbers'!O:O,"N")+COUNTIF('Hair & barbers'!Q:Q,"Already has website") -> 0 | E6: =COUNT('Hair & barbers'!P:P) -> 0 | F6: =COUNTIF('Hair & barbers'!Q:Q,"Interested - send preview")+COUNTIF('Hair & barbers'!Q:Q,"Preview sent") -> 0 | G6: =COUNTIF('Hair & barbers'!Q:Q,"Won") -> 0
A7: Garages & motor | B7: =COUNTA('Garages & motor'!B:B)-1 -> 192 | C7: =COUNTIF('Garages & motor'!O:O,"Y") -> 0 | D7: =COUNTIF('Garages & motor'!O:O,"N")+COUNTIF('Garages & motor'!Q:Q,"Already has website") -> 0 | E7: =COUNT('Garages & motor'!P:P) -> 0 | F7: =COUNTIF('Garages & motor'!Q:Q,"Interested - send preview")+COUNTIF('Garages & motor'!Q:Q,"Preview sent") -> 0 | G7: =COUNTIF('Garages & motor'!Q:Q,"Won") -> 0
A8: Beauty & nails | B8: =COUNTA('Beauty & nails'!B:B)-1 -> 165 | C8: =COUNTIF('Beauty & nails'!O:O,"Y") -> 0 | D8: =COUNTIF('Beauty & nails'!O:O,"N")+COUNTIF('Beauty & nails'!Q:Q,"Already has website") -> 0 | E8: =COUNT('Beauty & nails'!P:P) -> 0 | F8: =COUNTIF('Beauty & nails'!Q:Q,"Interested - send preview")+COUNTIF('Beauty & nails'!Q:Q,"Preview sent") -> 0 | G8: =COUNTIF('Beauty & nails'!Q:Q,"Won") -> 0
A9: Builders & roofers | B9: =COUNTA('Builders & roofers'!B:B)-1 -> 134 | C9: =COUNTIF('Builders & roofers'!O:O,"Y") -> 0 | D9: =COUNTIF('Builders & roofers'!O:O,"N")+COUNTIF('Builders & roofers'!Q:Q,"Already has website") -> 0 | E9: =COUNT('Builders & roofers'!P:P) -> 0 | F9: =COUNTIF('Builders & roofers'!Q:Q,"Interested - send preview")+COUNTIF('Builders & roofers'!Q:Q,"Preview sent") -> 0 | G9: =COUNTIF('Builders & roofers'!Q:Q,"Won") -> 0
A10: Pet care | B10: =COUNTA('Pet care'!B:B)-1 -> 118 | C10: =COUNTIF('Pet care'!O:O,"Y") -> 0 | D10: =COUNTIF('Pet care'!O:O,"N")+COUNTIF('Pet care'!Q:Q,"Already has website") -> 0 | E10: =COUNT('Pet care'!P:P) -> 0 | F10: =COUNTIF('Pet care'!Q:Q,"Interested - send preview")+COUNTIF('Pet care'!Q:Q,"Preview sent") -> 0 | G10: =COUNTIF('Pet care'!Q:Q,"Won") -> 0
A11: Painters & decorators | B11: =COUNTA('Painters & decorators'!B:B)-1 -> 85 | C11: =COUNTIF('Painters & decorators'!O:O,"Y") -> 0 | D11: =COUNTIF('Painters & decorators'!O:O,"N")+COUNTIF('Painters & decorators'!Q:Q,"Already has website") -> 0 | E11: =COUNT('Painters & decorators'!P:P) -> 0 | F11: =COUNTIF('Painters & decorators'!Q:Q,"Interested - send preview")+COUNTIF('Painters & decorators'!Q:Q,"Preview sent") -> 0 | G11: =COUNTIF('Painters & decorators'!Q:Q,"Won") -> 0
A12: Cleaning | B12: =COUNTA(Cleaning!B:B)-1 -> 71 | C12: =COUNTIF(Cleaning!O:O,"Y") -> 0 | D12: =COUNTIF(Cleaning!O:O,"N")+COUNTIF(Cleaning!Q:Q,"Already has website") -> 0 | E12: =COUNT(Cleaning!P:P) -> 0 | F12: =COUNTIF(Cleaning!Q:Q,"Interested - send preview")+COUNTIF(Cleaning!Q:Q,"Preview sent") -> 0 | G12: =COUNTIF(Cleaning!Q:Q,"Won") -> 0
A13: Gardening & landscaping | B13: =COUNTA('Gardening & landscaping'!B:B)-1 -> 68 | C13: =COUNTIF('Gardening & landscaping'!O:O,"Y") -> 0 | D13: =COUNTIF('Gardening & landscaping'!O:O,"N")+COUNTIF('Gardening & landscaping'!Q:Q,"Already has website") -> 0 | E13: =COUNT('Gardening & landscaping'!P:P) -> 0 | F13: =COUNTIF('Gardening & landscaping'!Q:Q,"Interested - send preview")+COUNTIF('Gardening & landscaping'!Q:Q,"Preview sent") -> 0 | G13: =COUNTIF('Gardening & landscaping'!Q:Q,"Won") -> 0
A14: Electricians | B14: =COUNTA(Electricians!B:B)-1 -> 66 | C14: =COUNTIF(Electricians!O:O,"Y") -> 0 | D14: =COUNTIF(Electricians!O:O,"N")+COUNTIF(Electricians!Q:Q,"Already has website") -> 0 | E14: =COUNT(Electricians!P:P) -> 0 | F14: =COUNTIF(Electricians!Q:Q,"Interested - send preview")+COUNTIF(Electricians!Q:Q,"Preview sent") -> 0 | G14: =COUNTIF(Electricians!Q:Q,"Won") -> 0
A15: Plumbing & heating | B15: =COUNTA('Plumbing & heating'!B:B)-1 -> 61 | C15: =COUNTIF('Plumbing & heating'!O:O,"Y") -> 0 | D15: =COUNTIF('Plumbing & heating'!O:O,"N")+COUNTIF('Plumbing & heating'!Q:Q,"Already has website") -> 0 | E15: =COUNT('Plumbing & heating'!P:P) -> 0 | F15: =COUNTIF('Plumbing & heating'!Q:Q,"Interested - send preview")+COUNTIF('Plumbing & heating'!Q:Q,"Preview sent") -> 0 | G15: =COUNTIF('Plumbing & heating'!Q:Q,"Won") -> 0
A16: Tattoo & piercing | B16: =COUNTA('Tattoo & piercing'!B:B)-1 -> 57 | C16: =COUNTIF('Tattoo & piercing'!O:O,"Y") -> 0 | D16: =COUNTIF('Tattoo & piercing'!O:O,"N")+COUNTIF('Tattoo & piercing'!Q:Q,"Already has website") -> 0 | E16: =COUNT('Tattoo & piercing'!P:P) -> 0 | F16: =COUNTIF('Tattoo & piercing'!Q:Q,"Interested - send preview")+COUNTIF('Tattoo & piercing'!Q:Q,"Preview sent") -> 0 | G16: =COUNTIF('Tattoo & piercing'!Q:Q,"Won") -> 0
A17: Fitness & driving | B17: =COUNTA('Fitness & driving'!B:B)-1 -> 56 | C17: =COUNTIF('Fitness & driving'!O:O,"Y") -> 0 | D17: =COUNTIF('Fitness & driving'!O:O,"N")+COUNTIF('Fitness & driving'!Q:Q,"Already has website") -> 0 | E17: =COUNT('Fitness & driving'!P:P) -> 0 | F17: =COUNTIF('Fitness & driving'!Q:Q,"Interested - send preview")+COUNTIF('Fitness & driving'!Q:Q,"Preview sent") -> 0 | G17: =COUNTIF('Fitness & driving'!Q:Q,"Won") -> 0
A18: Locksmiths & handymen | B18: =COUNTA('Locksmiths & handymen'!B:B)-1 -> 40 | C18: =COUNTIF('Locksmiths & handymen'!O:O,"Y") -> 0 | D18: =COUNTIF('Locksmiths & handymen'!O:O,"N")+COUNTIF('Locksmiths & handymen'!Q:Q,"Already has website") -> 0 | E18: =COUNT('Locksmiths & handymen'!P:P) -> 0 | F18: =COUNTIF('Locksmiths & handymen'!Q:Q,"Interested - send preview")+COUNTIF('Locksmiths & handymen'!Q:Q,"Preview sent") -> 0 | G18: =COUNTIF('Locksmiths & handymen'!Q:Q,"Won") -> 0
A19: Florists & gifts | B19: =COUNTA('Florists & gifts'!B:B)-1 -> 12 | C19: =COUNTIF('Florists & gifts'!O:O,"Y") -> 0 | D19: =COUNTIF('Florists & gifts'!O:O,"N")+COUNTIF('Florists & gifts'!Q:Q,"Already has website") -> 0 | E19: =COUNT('Florists & gifts'!P:P) -> 0 | F19: =COUNTIF('Florists & gifts'!Q:Q,"Interested - send preview")+COUNTIF('Florists & gifts'!Q:Q,"Preview sent") -> 0 | G19: =COUNTIF('Florists & gifts'!Q:Q,"Won") -> 0
A20: Total | B20: =SUM(B5:B19) -> 1660 | C20: =SUM(C5:C19) -> 0 | D20: =SUM(D5:D19) -> 0 | E20: =SUM(E5:E19) -> 0 | F20: =SUM(F5:F19) -> 0 | G20: =SUM(G5:G19) -> 0
A22: How to use
A23: • Each industry has its own tab, ranked best lead first (busy, good rating, mobile number, no website at all).
A24: • Green rows = your first 8 leads (already researched, see Notes).
A25: • Red "Check first" text = a similar name has a website somewhere, so look it up before calling.
A26: • Yellow columns are for you to fill in. Example: Checked = Y · Called = 17/10/2026 · Outcome = Call back · Notes = "Owner Dave, ring Mon 3pm".
A27: • Checked = N means you found a website, so it counts as "Already has website".
A28: • The "All leads" tab is a separate copy. Log calls on the industry tabs so the totals above stay right.
A29: • Always do a quick Google search of the exact name + town before calling.

Sheet Food & drink
A1: Rank | B1: Business name | C1: Category | D1: Phone | E1: Website status | F1: Website | G1: Check first | H1: Rating | I1: Reviews | J1: Town | K1: Postcode | L1: Address | M1: Best time to call | N1: Google Maps | O1: Checked no website? (Y/N) | P1: Called (date) | Q1: Outcome | R1: Notes
A2: 1 | B2: Bella Sorrento | C2: Italian restaurant | D2: 07522 199382 | E2: Social / booking page only | F2: http://www.facebook.com/bellasorrentostowmarket | H2: 4.6 | I2: 225 | J2: Stowmarket | K2: IP14 1DP | L2: 16 Market Pl, Stowmarket IP14 1DP | M2: 2:30–4:30pm (between lunch & dinner), or ~10am | N2: Open map | R2: First list. Preview built: bella-sorrento-preview.vercel.app
A3: 2 | B3: The Hidden Garden Cafe Ipswich | C3: Coffee Shop | D3: 07951 965152 | E3: None | H3: 5 | I3: 23 | J3: Ipswich | K3: IP1 1XF | L3: 15 St Peter's St, Ipswich IP1 1XF | M3: 2:30–4:30pm (between lunch & dinner), or ~10am | N3: Open map | R3: First list (Karen). Workshops/jazz nights, nowhere to list events
A4: 3 | B4: Golden Garden | C4: Chinese takeaway | D4: 01449 613389 | E4: None | H4: 4.3 | I4: 100 | J4: Stowmarket | L4: 4 Wolsey Rd, Stowmarket | M4: 2:30–4:30pm (between lunch & dinner), or ~10am | R4: First list. Phone orders only. Not picked up by the Google search
A5: 4 | B5: Stowupland Fish & Chip Shop | C5: Takeaway | D5: 07849 055080 | E5: None | H5: 4.7 | I5: 400 | J5: Stowmarket | K5: IP14 4AD | L5: Thorney Grn, Stowupland, Stowmarket IP14 4AD | M5: 2:30–4:30pm (between lunch & dinner), or ~10am | N5: Open map
A6: 5 | B6: Wilcrofts Cafe | C6: Cafe | D6: 07931 241268 | E6: None | H6: 4.6 | I6: 386 | J6: Bury Saint Edmunds | K6: IP33 1EB | L6: 13 Brentgovel St, Bury St Edmunds, Bury Saint Edmunds IP33 1EB | M6: 2:30–4:30pm (between lunch & dinner), or ~10am | N6: Open map
A7: 6 | B7: Cafe Kottani | C7: Cafe | D7: 07766 352972 | E7: None | H7: 4.7 | I7: 343 | J7: Bury Saint Edmunds | K7: IP33 1DW | L7: 30 Butter Market, Bury St Edmunds, Bury Saint Edmunds IP33 1DW | M7: 2:30–4:30pm (between lunch & dinner), or ~10am | N7: Open map
A8: 7 | B8: The Chippy | C8: Takeaway | D8: 07716 795854 | E8: None | H8: 4.6 | I8: 321 | J8: Lowestoft | K8: NR33 0BB | L8: 174-176 London Rd S, Lowestoft NR33 0BB | M8: 2:30–4:30pm (between lunch & dinner), or ~10am | N8: Open map
A9: 8 | B9: Cumberland Fish Bar | C9: Fish & chips shop | D9: 01394 382608 | E9: None | H9: 4.5 | I9: 385 | J9: Woodbridge | K9: IP12 4AB | L9: 2 Cumberland St, Woodbridge IP12 4AB | M9: 2:30–4:30pm (between lunch & dinner), or ~10am | N9: Open map
A10: 9 | B10: Starburger | C10: Restaurant | D10: 01440 714148 | E10: None | H10: 4.7 | I10: 366 | J10: Haverhill | K10: CB9 9DZ | L10: 7 Queen St, Haverhill CB9 9DZ | M10: 2:30–4:30pm (between lunch & dinner), or ~10am | N10: Open map
A11: 10 | B11: Street Cafe | C11: Cafe | D11: 01638 428099 | E11: None | H11: 4.6 | I11: 363 | J11: Newmarket | K11: CB8 8JH | L11: 81 High St, Newmarket CB8 8JH | M11: 2:30–4:30pm (between lunch & dinner), or ~10am | N11: Open map
A12: 11 | B12: Orwell Fish & Chips | C12: Takeaway | D12: 01394 813813 | E12: None | H12: 4.9 | I12: 346 | J12: Felixstowe | K12: IP11 7NY | L12: 9-11 Orwell Rd, Felixstowe IP11 7NY | M12: 2:30–4:30pm (between lunch & dinner), or ~10am | N12: Open map
A13: 12 | B13: Gulliver's Wife Café | C13: Cafe | D13: 01394 285626 | E13: None | H13: 4.8 | I13: 334 | J13: Felixstowe | K13: IP11 2AH | L13: 47 Undercliff Rd W, Felixstowe IP11 2AH | M13: 2:30–4:30pm (between lunch & dinner), or ~10am | N13: Open map
A14: 13 | B14: The Rampant Horse Inn | C14: Pub | D14: 01449 722044 | E14: None | H14: 4.6 | I14: 311 | J14: Ipswich | K14: IP6 8AU | L14: Coddenham Rd, Needham Market, Ipswich IP6 8AU | M14: 2:30–4:30pm (between lunch & dinner), or ~10am | N14: Open map
A15: 14 | B15: The Cock Inn | C15: Pub | D15: 07751 842829 | E15: Social / booking page only | F15: https://linktr.ee/thecockinnclare | H15: 4.6 | I15: 287 | J15: Sudbury | K15: CO10 8PX | L15: 3 Callis St, Clare, Sudbury CO10 8PX | M15: 2:30–4:30pm (between lunch & dinner), or ~10am | N15: Open map
A16: 15 | B16: Valley Way Fish & Chips | C16: Takeaway | D16: 01638 331087 | E16: None | H16: 4.8 | I16: 280 | J16: Newmarket | K16: CB8 0QL | L16: 78 Valley Way, Newmarket CB8 0QL | M16: 2:30–4:30pm (between lunch & dinner), or ~10am | N16: Open map
A17: 16 | B17: Mrs T's Fish & Chips | C17: Takeaway | D17: 07777 380982 | E17: None | H17: 4.7 | I17: 808 | J17: Blackshore | K17: IP18 6TA | L17: Southwold Hbr, Southwold, Blackshore IP18 6TA | M17: 2:30–4:30pm (between lunch & dinner), or ~10am | N17: Open map
A18: 17 | B18: Gun Hill Beach Kiosk | C18: Cafe | D18: 07446 023879 | E18: None | H18: 4.6 | I18: 581 | J18: Southwold | K18: IP18 6HF | L18: Southwold IP18 6HF | M18: 2:30–4:30pm (between lunch & dinner), or ~10am | N18: Open map
A19: 18 | B19: The Tea Shed Cafe, Restaurant | C19: Coffee Shop | D19: 07429 081962 | E19: None | H19: 4.5 | I19: 403 | J19: Southwold | K19: IP18 6TT | L19: The Green, Walberswick, Southwold IP18 6TT | M19: 2:30–4:30pm (between lunch & dinner), or ~10am | N19: Open map
A20: 19 | B20: The Ram | C20: Hotel | D20: 01842 810275 | E20: None | H20: 4.2 | I20: 363 | J20: Brandon | K20: IP27 0AX | L20: High St, Brandon IP27 0AX | M20: 2:30–4:30pm (between lunch & dinner), or ~10am | N20: Open map
A21: 20 | B21: White Horse Felixstowe | C21: Pub | D21: 01394 277496 | E21: None | H21: 4.2 | I21: 350 | J21: Felixstowe | K21: IP11 9NF | L21: 33 Church Rd, Felixstowe IP11 9NF | M21: 2:30–4:30pm (between lunch & dinner), or ~10am | N21: Open map
A22: 21 | B22: Melton Fish Bar | C22: Fish & chips shop | D22: 01394 382319 | E22: None | H22: 4.3 | I22: 339 | J22: Woodbridge | K22: IP12 1PT | L22: 1 Station Rd, Melton, Woodbridge IP12 1PT | M22: 2:30–4:30pm (between lunch & dinner), or ~10am | N22: Open map
A23: 22 | B23: Beccles Fish Bar | C23: Takeaway | D23: 01502 717306 | E23: None | H23: 4.3 | I23: 310 | J23: Beccles | K23: NR34 9AD | L23: 21 Smallgate, Beccles NR34 9AD | M23: 2:30–4:30pm (between lunch & dinner), or ~10am | N23: Open map
A24: 23 | B24: Eye Fish & Chip Shop | C24: Takeaway | D24: 01379 308680 | E24: None | H24: 4.5 | I24: 258 | J24: Eye | K24: IP23 7AG | L24: 6 Lambseth St, Eye IP23 7AG | M24: 2:30–4:30pm (between lunch & dinner), or ~10am | N24: Open map
A25: 24 | B25: Dolphin fish bar and restaurant | C25: Takeaway | D25: 01502 581441 | E25: None | H25: 4.3 | I25: 282 | J25: Lowestoft | K25: NR32 2AG | L25: 117 Bevan St E, Lowestoft NR32 2AG | M25: 2:30–4:30pm (between lunch & dinner), or ~10am | N25: Open map
A26: 25 | B26: Buttercross Garden Cafe | C26: Cafe | D26: 01986 513210 | E26: None | H26: 4.4 | I26: 280 | J26: Bungay | K26: NR35 1AU | L26: 6 Cross St, Bungay NR35 1AU | M26: 2:30–4:30pm (between lunch & dinner), or ~10am | N26: Open map
A27: 26 | B27: Has Bond's & Son | C27: Takeaway | D27: 07467 388083 | E27: None | H27: 4.6 | I27: 187 | J27: Ipswich | K27: IP6 8AG | L27: 2 Bridge St, Needham Market, Ipswich IP6 8AG | M27: 2:30–4:30pm (between lunch & dinner), or ~10am | N27: Open map
A28: 27 | B28: J's Traditional Fish & Chips at Crown Point | C28: Takeaway | D28: 07746 513941 | E28: None | H28: 4.2 | I28: 489 | J28: Ipswich | K28: IP12 4RX | L28: Crown Point Felixstowe Road Martlesham Woodbridge, Martlesham, Ipswich IP12 4RX | M28: 2:30–4:30pm (between lunch & dinner), or ~10am | N28: Open map
A29: 28 | B29: Four Three Pizza | C29: Pizza restaurant | D29: 01394 447319 | E29: Social / booking page only | F29: https://www.facebook.com/Four-Three-Pizza-100283511805681/ | H29: 4.8 | I29: 370 | J29: Felixstowe | K29: IP11 2AD | L29: 49 Undercliff Rd W, Felixstowe IP11 2AD | M29: 2:30–4:30pm (between lunch & dinner), or ~10am | N29: Open map
A30: 29 | B30: The Stables Coffee Shop & Sandwich Bar | C30: Coffee Shop | D30: 01473 736444 | E30: Social / booking page only | F30: https://www.facebook.com/thestablescoffeeshop/ | H30: 4.5 | I30: 346 | J30: Ipswich | K30: IP10 0BJ | L30: Brightwell Barns, Ipswich Rd, Ipswich IP10 0BJ | M30: 2:30–4:30pm (between lunch & dinner), or ~10am | N30: Open map
A31: 30 | B31: Flying Fifteens | C31: Tea room | D31: 01502 588422 | E31: Social / booking page only | F31: https://www.facebook.com/theflyingfifteens/ | H31: 4.6 | I31: 340 | J31: Lowestoft | K31: NR33 0QG | L31: 19A Esplanade, Lowestoft NR33 0QG | M31: 2:30–4:30pm (between lunch & dinner), or ~10am | N31: Open map
A32: 31 | B32: Trawler’s Catch | C32: Takeaway | D32: 01728 605741 | E32: Social / booking page only | F32: https://www.facebook.com/TrawlersCatchSax/ | H32: 4.5 | I32: 326 | J32: Saxmundham | K32: IP17 1AJ | L32: 37 High St, Saxmundham IP17 1AJ | M32: 2:30–4:30pm (between lunch & dinner), or ~10am | N32: Open map
A33: 32 | B33: Bell Inn Kesgrave | C33: Pub | D33: 01473 622045 | E33: Social / booking page only | F33: https://www.facebook.com/pages/The-Bell-Kesgrave/434304113268813 | H33: 4.5 | I33: 303 | J33: Ipswich | K33: IP5 1AA | L33: 129 Main Rd, Kesgrave, Ipswich IP5 1AA | M33: 2:30–4:30pm (between lunch & dinner), or ~10am | N33: Open map
A34: 33 | B34: Centre Cafe | C34: Cafe | D34: 01842 811132 | E34: None | H34: 4.6 | I34: 242 | J34: Brandon | K34: IP27 0AQ | L34: 43, 41A High St, Brandon IP27 0AQ | M34: 2:30–4:30pm (between lunch & dinner), or ~10am | N34: Open map
A35: 34 | B35: Peyton Plaice | C35: Takeaway | D35: 01284 766118 | E35: None | H35: 4.5 | I35: 230 | J35: Bury Saint Edmunds | K35: IP32 7BE | L35: Unit 1a, Barton Business Centre, Barton Rd, Bury St Edmunds, Bury Saint Edmunds IP32 7BE | M35: 2:30–4:30pm (between lunch & dinner), or ~10am | N35: Open map
A36: 35 | B36: West End Fish & Chips | C36: Takeaway | D36: 01284 703523 | E36: None | H36: 4.6 | I36: 229 | J36: Bury Saint Edmunds | K36: IP33 3NZ | L36: 2 Out Westgate, Bury St Edmunds, Bury Saint Edmunds IP33 3NZ | M36: 2:30–4:30pm (between lunch & dinner), or ~10am | N36: Open map
A37: 36 | B37: Weavers Tea Room | C37: Tea room | D37: 01728 660548 | E37: None | H37: 4.8 | I37: 226 | J37: Saxmundham | K37: IP17 2JE | L37: 2 The Knoll, Peasenhall, Saxmundham IP17 2JE | M37: 2:30–4:30pm (between lunch & dinner), or ~10am | N37: Open map
A38: 37 | B38: Duncans Bakery | C38: Bakery | D38: 01473 626828 | E38: None | H38: 4.9 | I38: 224 | J38: Ipswich | K38: IP5 3SL | L38: The Square, Martlesham Heath, Martlesham, Ipswich IP5 3SL | M38: 2:30–4:30pm (between lunch & dinner), or ~10am | N38: Open map
A39: 38 | B39: Doh Pizzeria | C39: Pizza restaurant | D39: 01502 473888 | E39: None | H39: 4.7 | I39: 223 | J39: Southwold | K39: IP18 6DJ | L39: 51A High St, Southwold IP18 6DJ | M39: 2:30–4:30pm (between lunch & dinner), or ~10am | N39: Open map
A40: 39 | B40: Golden Fish | C40: Takeaway | D40: 01502 561307 | E40: Social / booking page only | F40: https://www.facebook.com/goldenfishlowestoft | H40: 4.6 | I40: 279 | J40: Lowestoft | K40: NR33 7JG | L40: 16 Blackheath Rd, Lowestoft NR33 7JG | M40: 2:30–4:30pm (between lunch & dinner), or ~10am | N40: Open map
...

Sheet Hair & barbers
A1: Rank | B1: Business name | C1: Category | D1: Phone | E1: Website status | F1: Website | G1: Check first | H1: Rating | I1: Reviews | J1: Town | K1: Postcode | L1: Address | M1: Best time to call | N1: Google Maps | O1: Checked no website? (Y/N) | P1: Called (date) | Q1: Outcome | R1: Notes
A2: 1 | B2: The Hair Co | C2: Hairdresser | D2: 01787 372722 | E2: Spam link (not theirs) | F2: https://detoaph.top/the-hair-co-7328505 | H2: 4.9 | I2: 80 | J2: Sudbury | M2: Weekday 10am–12pm or early afternoon (between clients) | R2: First list. Google Website button goes to a spam page, show them
A3: 2 | B3: Rise + Grind Barbershop | C3: Barber shop | E3: Booking page only (Booksy) | J3: Bury Saint Edmunds | M3: Walk in or Instagram DM | R3: First list (Kai & Dylan). No phone on Google
A4: 3 | B4: Baba-Z | C4: Barber shop | D4: 01473 411784 | E4: Social / booking page only | F4: https://www.facebook.com/BabaZeeIpswich | H4: 4.9 | I4: 358 | J4: Ipswich | K4: IP3 8JX | L4: 67 Foxhall Rd, Ipswich IP3 8JX | M4: Weekday 10am–12pm or early afternoon (between clients) | N4: Open map
A5: 4 | B5: Ipswich Nails Spa | C5: Barber shop | D5: 01473 557777 | E5: Social / booking page only | F5: https://instagram.com/ipswichnailsspa?igshid=YmMyMTA2M2Y= | H5: 4.6 | I5: 348 | J5: Ipswich | K5: IP4 1EJ | L5: 24 Carr St, Ipswich IP4 1EJ | M5: Weekday 10am–12pm or early afternoon (between clients) | N5: Open map
A6: 5 | B6: Razor King Stowmarket | C6: Barber shop | D6: 07789 022954 | E6: None | H6: 4.8 | I6: 167 | J6: Stowmarket | K6: IP14 1DL | L6: Crowe St, Stowmarket IP14 1DL | M6: Weekday 10am–12pm or early afternoon (between clients) | N6: Open map
A7: 6 | B7: Golden Scissors | C7: Barber shop | D7: 07788 174101 | E7: Social / booking page only | F7: https://instagram.com/goldenmagicscissorsbury?igshid=M29zaHE2MWNmY3Ix | H7: 4.4 | I7: 244 | J7: Bury Saint Edmunds | K7: IP33 1BJ | L7: The Traverse, Bury St Edmunds, Bury Saint Edmunds IP33 1BJ | M7: Weekday 10am–12pm or early afternoon (between clients) | N7: Open map
A8: 7 | B8: VIP cuts | C8: Barber shop | D8: 07869 141516 | E8: None | H8: 5 | I8: 153 | J8: Felixstowe | K8: IP11 7PD | L8: Unit 2, 25 Crescent Rd, Felixstowe IP11 7PD | M8: Weekday 10am–12pm or early afternoon (between clients) | N8: Open map
A9: 8 | B9: ARONS CUTS | C9: Barber shop | D9: 01473 808718 | E9: None | H9: 4.8 | I9: 210 | J9: Ipswich | K9: IP3 9JH | L9: 296 Nacton Rd, Ipswich IP3 9JH | M9: Weekday 10am–12pm or early afternoon (between clients) | N9: Open map
A10: 9 | B10: Kings & Queens Hairdressers & Beauty | C10: Hairdresser | D10: 07738 370944 | E10: None | H10: 4.8 | I10: 138 | J10: Newmarket | K10: CB8 8EQ | L10: Kings & Queens, 13 The Rookery, The Guineas, Shopping Centre, Newmarket CB8 8EQ | M10: Weekday 10am–12pm or early afternoon (between clients) | N10: Open map
A11: 10 | B11: Spikes and Ponies | C11: Hairdresser | D11: 07535 646508 | E11: None | H11: 4.8 | I11: 137 | J11: Newmarket | K11: CB8 7RX | L11: Shop 3, Brickfields Ave, Newmarket CB8 7RX | M11: Weekday 10am–12pm or early afternoon (between clients) | N11: Open map
A12: 11 | B12: Look Sharp | C12: Barber shop | D12: 07459 323458 | E12: None | H12: 4.7 | I12: 136 | J12: Felixstowe | K12: IP11 7DU | L12: 172 Hamilton Rd, Felixstowe IP11 7DU | M12: Weekday 10am–12pm or early afternoon (between clients) | N12: Open map
A13: 12 | B13: The Barbers | C13: Barber shop | D13: 01842 550889 | E13: None | H13: 4.6 | I13: 191 | J13: Brandon | K13: IP27 0AQ | L13: 22 High St, Brandon IP27 0AQ | M13: Weekday 10am–12pm or early afternoon (between clients) | N13: Open map
A14: 13 | B14: Lotus Nails Spa | C14: Hairdresser | D14: 01473 217773 | E14: None | H14: 4.2 | I14: 210 | J14: Ipswich | K14: IP4 1EB | L14: 26 Upper Brook St, Ipswich IP4 1EB | M14: Weekday 10am–12pm or early afternoon (between clients) | N14: Open map
A15: 14 | B15: Top Fade Barber | C15: Barber shop | D15: 07886 340927 | E15: None | H15: 4.8 | I15: 118 | J15: Lowestoft | K15: NR33 0DS | L15: 243 London Rd S, Lowestoft NR33 0DS | M15: Weekday 10am–12pm or early afternoon (between clients) | N15: Open map
A16: 15 | B16: King’s scissors | C16: Barber shop | D16: 07362 394043 | E16: None | H16: 4.9 | I16: 113 | J16: Newmarket | K16: CB8 8DN | L16: 12 Old Station Rd, Newmarket CB8 8DN | M16: Weekday 10am–12pm or early afternoon (between clients) | N16: Open map
A17: 16 | B17: Walton Barbers | C17: Barber shop | D17: 07826 539691 | E17: None | H17: 4.8 | I17: 108 | J17: Felixstowe | K17: IP11 9DS | L17: 222 High St, Felixstowe IP11 9DS | M17: Weekday 10am–12pm or early afternoon (between clients) | N17: Open map
A18: 17 | B18: Classic barbershop | C18: Barber shop | D18: 07376 665786 | E18: None | H18: 4.9 | I18: 103 | J18: Newmarket | K18: CB8 8EE | L18: 6 Market St, Newmarket CB8 8EE | M18: Weekday 10am–12pm or early afternoon (between clients) | N18: Open map
A19: 18 | B19: THE MOUSTACHE BARBERS | C19: Barber shop | D19: 07717 125332 | E19: Social / booking page only | F19: https://www.instagram.com/themoustachebarbers/ | H19: 4.5 | I19: 154 | J19: Newmarket | K19: CB8 8NA | L19: 35 High St, Newmarket CB8 8NA | M19: Weekday 10am–12pm or early afternoon (between clients) | N19: Open map
A20: 19 | B20: Kenny's Barbershop | C20: Barber shop | D20: 07493 823883 | E20: None | H20: 4.9 | I20: 96 | J20: Lowestoft | K20: NR32 1XN | L20: 79 High St, Lowestoft NR32 1XN | M20: Weekday 10am–12pm or early afternoon (between clients) | N20: Open map
A21: 20 | B21: Sharp cut | C21: Barber shop | D21: 07926 779222 | E21: None | H21: 5 | I21: 95 | J21: Ipswich | K21: IP3 9EX | L21: 52 Queen's Way, Ipswich IP3 9EX | M21: Weekday 10am–12pm or early afternoon (between clients) | N21: Open map
A22: 21 | B22: Isaac's Barbershop | C22: Barber shop | D22: 01394 382348 | E22: Social / booking page only | F22: https://m.facebook.com/Isaacs.barbershop.ltd | H22: 4.9 | I22: 415 | J22: Woodbridge | K22: IP12 1JX | L22: Warwick Ave, Woodbridge IP12 1JX | M22: Weekday 10am–12pm or early afternoon (between clients) | N22: Open map
A23: 22 | B23: Lookin' Sharp Barbers | C23: Barber shop | D23: 07841 678407 | E23: None | H23: 4.9 | I23: 91 | J23: Ipswich | K23: IP2 0EH | L23: 11 Compair Cres, Ipswich IP2 0EH | M23: Weekday 10am–12pm or early afternoon (between clients) | N23: Open map
A24: 23 | B24: S&S Barber | C24: Barber shop | D24: 07378 454411 | E24: None | H24: 4.5 | I24: 91 | J24: Woodbridge | K24: IP12 | L24: 4a Cumberland St, Woodbridge IP12 | M24: Weekday 10am–12pm or early afternoon (between clients) | N24: Open map
A25: 24 | B25: Yonney Barbers | C25: Barber shop | D25: 07540 428000 | E25: Social / booking page only | F25: https://m.facebook.com/pages/category/Barber-Shop/Yonneys-Barber-Shop-1481658455250613/ | H25: 4.9 | I25: 145 | J25: Lowestoft | K25: NR33 0DR | L25: 189 London Rd S, Lowestoft NR33 0DR | M25: Weekday 10am–12pm or early afternoon (between clients) | N25: Open map
A26: 25 | B26: Brandon Town Barbers | C26: Barber shop | D26: 07733 467701 | E26: None | H26: 4.9 | I26: 85 | J26: Brandon | K26: IP27 0AU | L26: 71 High St, Brandon IP27 0AU | M26: Weekday 10am–12pm or early afternoon (between clients) | N26: Open map
A27: 26 | B27: Traditional Turkish Barber | C27: Barber shop | D27: 07915 026618 | E27: None | H27: 4.9 | I27: 77 | J27: Ipswich | K27: IP4 4QA | L27: 470 Woodbridge Rd, Ipswich IP4 4QA | M27: Weekday 10am–12pm or early afternoon (between clients) | N27: Open map
A28: 27 | B28: Emanuel Barbers | C28: Barber shop | D28: 07869 165492 | E28: None | H28: 4.9 | I28: 74 | J28: Beccles | K28: NR34 9TB | L28: 18 Blyburgate, Beccles NR34 9TB | M28: Weekday 10am–12pm or early afternoon (between clients) | N28: Open map
A29: 28 | B29: NEXTGEN BARBERZ | C29: Barber shop | D29: 07859 854985 | E29: None | H29: 4.9 | I29: 74 | J29: Ipswich | K29: IP2 9RR | L29: 16 Ellenbrook Rd, Ipswich IP2 9RR | M29: Weekday 10am–12pm or early afternoon (between clients) | N29: Open map
A30: 29 | B30: Brothers Cuts | C30: Barber shop | D30: 07469 273596 | E30: None | H30: 4.8 | I30: 70 | J30: Ipswich | K30: IP1 3JX | L30: 12 High St, Ipswich IP1 3JX | M30: Weekday 10am–12pm or early afternoon (between clients) | N30: Open map
A31: 30 | B31: FIRST CLASS BARBERS SUDBURY | C31: Barber shop | D31: 07392 928065 | E31: None | H31: 5 | I31: 69 | J31: Sudbury | K31: CO10 2TP | L31: Unit 3, First Class Barbers, 101 East St, Sudbury CO10 2TP | M31: Weekday 10am–12pm or early afternoon (between clients) | N31: Open map
A32: 31 | B32: The Shear Club | C32: Barber shop | D32: 01473 288445 | E32: Social / booking page only | F32: https://booksy.com/en-gb/55881_the-shear-club_barber-shop_284972_ipswich | H32: 4.7 | I32: 186 | J32: Ipswich | K32: IP3 0BH | L32: 205 Duke St, Ipswich IP3 0BH | M32: Weekday 10am–12pm or early afternoon (between clients) | N32: Open map
A33: 32 | B33: Fleet's Barber Shop | C33: Barber shop | D33: 01502 717555 | E33: None | H33: 4.7 | I33: 128 | J33: Beccles | K33: NR34 9TQ | L33: 46 Blyburgate, Beccles NR34 9TQ | M33: Weekday 10am–12pm or early afternoon (between clients) | N33: Open map
A34: 33 | B34: TWELVE Mens Salon | C34: Barber shop | D34: 07707 717876 | E34: Social / booking page only | F34: https://twelvemenssalon.booksy.com/ | H34: 5 | I34: 117 | J34: Stowmarket | K34: IP14 1ES | L34: Station Rd W, Stowmarket IP14 1ES | M34: Weekday 10am–12pm or early afternoon (between clients) | N34: Open map
A35: 34 | B35: Magic Touch Traditional Turkish Barber | C35: Hairdresser | D35: 07452 847416 | E35: None | H35: 5 | I35: 63 | J35: Lowestoft | K35: NR33 9JT | L35: 148 Bridge Rd, Lowestoft NR33 9JT | M35: Weekday 10am–12pm or early afternoon (between clients) | N35: Open map
A36: 35 | B36: Thurston barbers | C36: Barber shop | D36: 07503 128606 | E36: None | H36: 5 | I36: 59 | J36: Bury Saint Edmunds | K36: IP31 3QT | L36: 9 Barton Rd, Thurston, Bury Saint Edmunds IP31 3QT | M36: Weekday 10am–12pm or early afternoon (between clients) | N36: Open map
A37: 36 | B37: Simone Michelle the Hair salon | C37: Hairdresser | D37: 01394 283555 | E37: None | H37: 4.5 | I37: 113 | J37: Felixstowe | K37: IP11 9AA | L37: 73, 75 High Rd W, Felixstowe IP11 9AA | M37: Weekday 10am–12pm or early afternoon (between clients) | N37: Open map
A38: 37 | B38: David Sparkes Barber Shop | C38: Barber shop | D38: 07801 236602 | E38: None | H38: 5 | I38: 55 | J38: Ipswich | K38: IP4 4NB | L38: 721A Woodbridge Rd, Ipswich IP4 4NB | M38: Weekday 10am–12pm or early afternoon (between clients) | N38: Open map
A39: 38 | B39: Thirty nine’s Barber shop | C39: Barber shop | D39: 07436 809653 | E39: None | H39: 5 | I39: 54 | J39: Lowestoft | K39: NR32 2JQ | L39: 39 Hervey St, Lowestoft NR32 2JQ | M39: Weekday 10am–12pm or early afternoon (between clients) | N39: Open map
A40: 39 | B40: Gentlemens grooming | C40: Barber shop | D40: 07760 962175 | E40: None | H40: 5 | I40: 54 | J40: Newmarket | K40: CB8 8JP | L40: 120A High St, Newmarket CB8 8JP | M40: Weekday 10am–12pm or early afternoon (between clients) | N40: Open map
...

Sheet Garages & motor
A1: Rank | B1: Business name | C1: Category | D1: Phone | E1: Website status | F1: Website | G1: Check first | H1: Rating | I1: Reviews | J1: Town | K1: Postcode | L1: Address | M1: Best time to call | N1: Google Maps | O1: Checked no website? (Y/N) | P1: Called (date) | Q1: Outcome | R1: Notes
A2: 1 | B2: The Garage | C2: Vehicle Repair | D2: 01728 648859 | E2: None | H2: 4.8 | I2: 32 | J2: Saxmundham | K2: IP17 3NS | L2: Leiston Rd, Saxmundham IP17 3NS | M2: 8–9am or 4–5pm | N2: Open map | R2: First list (Nick), aka Middleton Garage
A3: 2 | B3: Brandon Hand Car Wash | C3: Car Wash | D3: 07454 343883 | E3: None | H3: 4.3 | I3: 287 | J3: Brandon | K3: IP27 0NX | L3: Mile End, Brandon IP27 0NX | M3: 8–9am or 4–5pm | N3: Open map
A4: 3 | B4: Ipswich Elite Tyres | C4: Tyre Shop | D4: 07496 396080 | E4: None | H4: 4.9 | I4: 238 | J4: Ipswich | K4: IP1 5NP | L4: 2 Goddard Rd, Ipswich IP1 5NP | M4: 8–9am or 4–5pm | N4: Open map
A5: 4 | B5: Eric Professional Hand Car Wash | C5: Car Wash | D5: 07446 705362 | E5: None | H5: 4.5 | I5: 203 | J5: Ipswich | K5: IP3 8DL | L5: Old station yard, Derby Rd, Ipswich IP3 8DL | M5: 8–9am or 4–5pm | N5: Open map
A6: 5 | B6: Pitstop Tyres | C6: Tyre Shop | D6: 01502 519154 | E6: Social / booking page only | F6: https://www.facebook.com/PitstopTyresLowestoft/ | H6: 4.8 | I6: 281 | J6: Lowestoft | K6: NR33 9QS | L6: 34 Colville Rd Works, Lowestoft NR33 9QS | M6: 8–9am or 4–5pm | N6: Open map
A7: 6 | B7: Beccles Car Wash | C7: Car Wash | D7: 07775 368820 | E7: None | H7: 4.1 | I7: 179 | J7: Beccles | K7: NR34 9QN | L7: Gresham Rd, Beccles NR34 9QN | M7: 8–9am or 4–5pm | N7: Open map
A8: 7 | B8: Fiveways Garage & Tyres | C8: Tyre Shop | D8: 01638 718448 | E8: None | H8: 4.5 | I8: 172 | J8: Bury Saint Edmunds | K8: IP28 6AE | L8: Fiveways tyre centre, fiveways garage, Fiveways Roundabout, Bury St Edmunds, Barton Mills, Bury Saint Edmunds IP28 6AE | M8: 8–9am or 4–5pm | N8: Open map
A9: 8 | B9: Stanton Hand Car Wash | C9: Car Wash | D9: 07568 403788 | E9: None | H9: 4.4 | I9: 145 | J9: Bury Saint Edmunds | K9: IP31 2BZ | L9: Stanton, Bury Saint Edmunds IP31 2BZ | M9: 8–9am or 4–5pm | N9: Open map
A10: 9 | B10: Mount Pleasant Hand Car Wash and Valeting Centre | C10: Car Wash | D10: 01440 762333 | E10: None | H10: 3.9 | I10: 222 | J10: Haverhill | K10: CB9 7RN | L10: Withersfield Rd, Haverhill CB9 7RN | M10: 8–9am or 4–5pm | N10: Open map
A11: 10 | B11: S W Mechanics (formerly B A mobile vehicle services) | C11: Vehicle Repair | D11: 07999 485587 | E11: None | H11: 4.7 | I11: 97 | J11: Ipswich | K11: IP1 5AP | L11: The Sterling Complex, Farthing Rd, Ipswich IP1 5AP | M11: 8–9am or 4–5pm | N11: Open map
A12: 11 | B12: Triple c automotive Ltd | C12: Vehicle Repair | D12: 01473 747779 | E12: None | H12: 4.8 | I12: 145 | J12: Ipswich | K12: IP1 5AP | L12: Farthing Rd, Ipswich IP1 5AP | M12: 8–9am or 4–5pm | N12: Open map
A13: 12 | B13: Langer Park Service Station | C13: Vehicle Repair | D13: 01394 284156 | E13: None | H13: 4.5 | I13: 143 | J13: Felixstowe | K13: IP11 2BS | L13: Langer Park Service Station, Langer Rd, Felixstowe IP11 2BS | M13: 8–9am or 4–5pm | N13: Open map
A14: 13 | B14: Beccles Tyre Centre Ltd | C14: Tyre Shop | D14: 01502 712113 | E14: Social / booking page only | F14: https://www.facebook.com/profile.php?id=100054596733057 | H14: 5 | I14: 199 | J14: Beccles | K14: NR34 7BF | L14: Tilia Ct, Beccles NR34 7BF | M14: 8–9am or 4–5pm | N14: Open map
A15: 14 | B15: Saxmundham Hand Car Wash | C15: Car Wash | D15: 07786 868160 | E15: None | H15: 4.2 | I15: 107 | J15: Saxmundham | K15: IP17 1AN | L15: B1121, Saxmundham IP17 1AN | M15: 8–9am or 4–5pm | N15: Open map
A16: 15 | B16: Fram Hand Car Wash | C16: Car Wash | D16: 07950 483515 | E16: None | H16: 4.8 | I16: 78 | J16: Woodbridge | K16: IP13 9LL | L16: 7 Woodbridge Rd, Framlingham, Woodbridge IP13 9LL | M16: 8–9am or 4–5pm | N16: Open map
A17: 16 | B17: Part Worn & New Tyres | C17: Tyre Shop | D17: 07400 098718 | E17: Social / booking page only | F17: https://www.facebook.com/pages/Bury-St-Edmunds-Hand-Car-Wash-Part-Worn-Tyres/1592208594387224?ref=hl | H17: 4 | I17: 154 | J17: Bury Saint Edmunds | K17: IP32 1AD | L17: Malthouse Ln, Bury St Edmunds, Bury Saint Edmunds IP32 1AD | M17: 8–9am or 4–5pm | N17: Open map
A18: 17 | B18: M K Autos | C18: Vehicle Repair | D18: 01359 245998 | E18: None | H18: 4.8 | I18: 128 | J18: Bury Saint Edmunds | K18: IP30 9HN | L18: Grove Ln, Elmswell, Bury Saint Edmunds IP30 9HN | M18: 8–9am or 4–5pm | N18: Open map
A19: 18 | B19: Alex Crow | C19: Vehicle Repair | D19: 01449 258185 | E19: None | H19: 4.9 | I19: 119 | J19: Stowmarket | K19: IP14 5AG | L19: Unit 5E, The Maltings Business Center, Stowupland Rd, Stowmarket IP14 5AG | M19: 8–9am or 4–5pm | N19: Open map
A20: 19 | B20: Hand Car Wash | C20: Car Wash | D20: 07453 304958 | E20: None | H20: 4 | I20: 91 | J20: Stowmarket | K20: IP14 1EQ | L20: Station Road East The Weighbrifge, Charringtons Yard, Stowmarket IP14 1EQ | M20: 8–9am or 4–5pm | N20: Open map
A21: 20 | B21: U-wash Launderette | C21: Laundry | D21: 07944 611767 | E21: None | H21: 4 | I21: 88 | J21: Felixstowe | K21: IP11 7HN | L21: 21 Constable Rd, Felixstowe IP11 7HN | M21: 8–9am or 4–5pm | N21: Open map
A22: 21 | B22: Professional Car Wash | C22: Car Wash | D22: 07716 100021 | E22: None | H22: 4.3 | I22: 88 | J22: Ipswich | K22: IP3 8AB | L22: 77 Fore Hamlet, Ipswich IP3 8AB | M22: 8–9am or 4–5pm | N22: Open map
A23: 22 | B23: Clarke Valeting | D23: 07557 145480 | E23: None | H23: 5 | I23: 54 | J23: Woodbridge | K23: IP12 2UF | L23: 9 Fountain Rd, Rendlesham, Woodbridge IP12 2UF | M23: 8–9am or 4–5pm | N23: Open map
A24: 23 | B24: M L Autocare | C24: Vehicle Repair | D24: 07568 213463 | E24: None | H24: 5 | I24: 51 | J24: Woodbridge | K24: IP12 4RF | L24: The St, Martlesham, Woodbridge IP12 4RF | M24: 8–9am or 4–5pm | N24: Open map
A25: 24 | B25: R J Car and Commercial | C25: Vehicle Repair | D25: 01473 250086 | E25: None | H25: 4.9 | I25: 107 | J25: Ipswich | K25: IP4 2ES | L25: 2 Hervey St, Ipswich IP4 2ES | M25: 8–9am or 4–5pm | N25: Open map
A26: 25 | B26: E.S AUTO TECH | C26: Vehicle Repair | D26: 07933 144133 | E26: Social / booking page only | F26: https://www.facebook.com/EastAnglia0/ | H26: 5 | I26: 105 | J26: Brandon | K26: IP27 0PD | L26: Unit 9, Beaumont Court, Brandon IP27 0PD | M26: 8–9am or 4–5pm | N26: Open map
A27: 26 | B27: Burkitts Lane Garage | C27: Vehicle Repair | D27: 01787 373030 | E27: None | H27: 4.8 | I27: 104 | J27: Sudbury | K27: CO10 1HB | L27: Burkitts Ln, Sudbury CO10 1HB | M27: 8–9am or 4–5pm | N27: Open map
A28: 27 | B28: Hillside Service Centre | C28: Vehicle Repair | D28: 01284 754646 | E28: None | H28: 4.8 | I28: 101 | J28: Bury Saint Edmunds | K28: IP32 7EA | L28: 18 Hillside Road, Bury St Edmunds, Bury Saint Edmunds IP32 7EA | M28: 8–9am or 4–5pm | N28: Open map
A29: 28 | B29: Haynings Service Station Ltd | C29: Vehicle Repair | D29: 01728 723528 | E29: None | H29: 4.7 | I29: 99 | J29: Woodbridge | K29: IP13 9DB | L29: 2 Saxmundham Rd, Framlingham, Woodbridge IP13 9DB | M29: 8–9am or 4–5pm | N29: Open map
A30: 29 | B30: On The Road Motor Services | C30: Vehicle Repair | D30: 07772 544842 | E30: None | H30: 5 | I30: 42 | J30: Beccles | K30: NR34 7FA | L30: Unit 10b, Boasts Industrial Park, College Ln, Beccles NR34 7FA | M30: 8–9am or 4–5pm | N30: Open map
A31: 30 | B31: Mobile mechanic Ipswich(cars and vans) | C31: Vehicle Repair | D31: 07462 487516 | E31: Social / booking page only | F31: https://www.facebook.com/carsandvansservicingandrepair | H31: 4.7 | I31: 96 | J31: Ipswich | K31: IP4 5LX | L31: Spring Rd, Ipswich IP4 5LX | M31: 8–9am or 4–5pm | N31: Open map
A32: 31 | B32: Elson hand car wash | C32: Car Wash | D32: 07378 857174 | E32: None | H32: 4.4 | I32: 65 | J32: Sudbury | K32: CO10 1TL | L32: 8-9 Old Market Place, Sudbury CO10 1TL | M32: 8–9am or 4–5pm | N32: Open map
A33: 32 | B33: Alex’s Brockford Prestige Car Wash & Detailing Center | C33: Car Wash | D33: 07482 900961 | E33: None | H33: 4.8 | I33: 37 | J33: Stowmarket | K33: IP14 5PF | L33: Norwich Rd, Stowmarket IP14 5PF | M33: 8–9am or 4–5pm | N33: Open map
A34: 33 | B34: Amazing Mobile Mechanic Newmarket | C34: Vehicle Repair | D34: 07345 636037 | E34: None | H34: 4.8 | I34: 35 | J34: Newmarket | K34: CB8 7BP | L34: 5 Bury Rd, Newmarket CB8 7BP | M34: 8–9am or 4–5pm | N34: Open map
A35: 34 | B35: Station Hand Car Wash | C35: Car Wash | D35: 01638 515486 | E35: None | H35: 3.5 | I35: 151 | J35: Bury Saint Edmunds | K35: IP32 1AD | L35: Malthouse Lane, Bury St Edmunds, Bury Saint Edmunds IP32 1AD | M35: 8–9am or 4–5pm | N35: Open map
A36: 35 | B36: Norwich Road Garage (Lowestoft) | C36: Vehicle Repair | D36: 01502 560456 | E36: None | H36: 4.5 | I36: 93 | J36: Lowestoft | K36: NR32 2BN | L36: 91 Norwich Rd, Norwich Road Industrial Estate, Lowestoft NR32 2BN | M36: 8–9am or 4–5pm | N36: Open map
A37: 36 | B37: M.D Saunders Auto Repair | C37: Vehicle Repair | D37: 01379 873569 | E37: None | H37: 4.9 | I37: 91 | J37: Eye | K37: IP23 7HN | L37: Broome Industrial Estate, Unit 16 Fortress Close, Eye IP23 7HN | M37: 8–9am or 4–5pm | N37: Open map
A38: 37 | B38: David Hughes and Son Ltd | C38: Vehicle Repair | D38: 01284 700055 | E38: None | H38: 4.9 | I38: 89 | J38: Bury Saint Edmunds | K38: IP32 7HX | L38: 15 & 16 Mercers Rd, Bury St Edmunds, Bury Saint Edmunds IP32 7HX | M38: 8–9am or 4–5pm | N38: Open map
A39: 38 | B39: Hand Car Wash | C39: Car Wash | D39: 07482 900961 | E39: None | H39: 4.6 | I39: 31 | J39: Stowmarket | K39: IP14 5PF | L39: A140, Stowmarket IP14 5PF | M39: 8–9am or 4–5pm | N39: Open map
A40: 39 | B40: Framlingham Car Sales. | C40: Car Dealer | D40: 07359 794988 | E40: None | H40: 4.6 | I40: 29 | J40: Woodbridge | K40: IP13 9RD | L40: Saxtead, Framlingham, Woodbridge IP13 9RD | M40: 8–9am or 4–5pm | N40: Open map
...

Sheet Beauty & nails
A1: Rank | B1: Business name | C1: Category | D1: Phone | E1: Website status | F1: Website | G1: Check first | H1: Rating | I1: Reviews | J1: Town | K1: Postcode | L1: Address | M1: Best time to call | N1: Google Maps | O1: Checked no website? (Y/N) | P1: Called (date) | Q1: Outcome | R1: Notes
A2: 1 | B2: T&A Nails Spa | C2: Nail Salon | D2: 07346 366456 | E2: Social / booking page only | F2: https://www.instagram.com/tanails.spa?igsh=MXh4cGFxaW51Y3I1cg%3D%3D&utm_source= | H2: 4.8 | I2: 331 | J2: Ipswich | K2: IP1 3BB | L2: Unit 14, Sailmakers Centre, Ipswich IP1 3BB | M2: Weekday 10am–12pm or early afternoon (between clients) | N2: Open map
A3: 2 | B3: Princess Nails | C3: Nail Salon | D3: 07735 889629 | E3: Social / booking page only | F3: https://www.instagram.com/princessnails424?igsh=MWo2anMweHB4cnV4MQ%3D%3D&utm_source= | H3: 4.9 | I3: 816 | J3: Ipswich | K3: IP4 1BA | L3: 22 Tacket St, Ipswich IP4 1BA | M3: Weekday 10am–12pm or early afternoon (between clients) | N3: Open map
A4: 3 | B4: Supreme nail | C4: Nail Salon | D4: 07878 253435 | E4: Social / booking page only | F4: https://www.appointfix.com/book/Supreme-nail | H4: 4.8 | I4: 197 | J4: Sudbury | K4: CO10 2ET | L4: 8A Gainsborough St, Sudbury CO10 2ET | M4: Weekday 10am–12pm or early afternoon (between clients) | N4: Open map
A5: 4 | B5: Bury Nail Spa and Beauty | C5: Beauty Salon | D5: 07719 785482 | E5: Social / booking page only | F5: https://www.instagram.com/burynailspaandbeauty?igsh=MTExOXR0dHY0dnBsZw%3D%3D&utm_source=qr | H5: 4.9 | I5: 175 | J5: Bury Saint Edmunds | K5: IP33 1SQ | L5: 3 St John's St, Bury St Edmunds, Bury Saint Edmunds IP33 1SQ | M5: Weekday 10am–12pm or early afternoon (between clients) | N5: Open map
A6: 5 | B6: Little Nails | C6: Nail Salon | D6: 07440 363138 | E6: None | H6: 4.7 | I6: 93 | J6: Stowmarket | K6: IP14 1AB | L6: Unit 9, old fox yard, 27 Ipswich St, Stowmarket IP14 1AB | M6: Weekday 10am–12pm or early afternoon (between clients) | N6: Open map
A7: 6 | B7: Last Night's Nails | C7: Nail Salon | D7: 07973 923042 | E7: None | H7: 5 | I7: 90 | J7: Ipswich | K7: IP4 4DB | L7: 171 Brunswick Rd, Ipswich IP4 4DB | M7: Weekday 10am–12pm or early afternoon (between clients) | N7: Open map
A8: 7 | B8: Felixstowe Nails Spa | C8: Nail Salon | D8: 01394 334504 | E8: Social / booking page only | F8: http://www.instagram.com/felixstowenailsspa | H8: 4.9 | I8: 201 | J8: Felixstowe | K8: IP11 7BL | L8: 123 Hamilton Rd, Felixstowe IP11 7BL | M8: Weekday 10am–12pm or early afternoon (between clients) | N8: Open map
A9: 8 | B9: Newmarket Nails & Spa | C9: Nail Salon | D9: 07466 032511 | E9: None | H9: 4.9 | I9: 74 | J9: Newmarket | K9: CB8 8DT | L9: 1 Old Station Rd, Newmarket CB8 8DT | M9: Weekday 10am–12pm or early afternoon (between clients) | N9: Open map
A10: 9 | B10: Zara’s Hair Studio | C10: Beauty Salon | D10: 07838 515994 | E10: None | H10: 5 | I10: 72 | J10: Ipswich | K10: IP4 2FB | L10: 304 Old Foundry Rd, Ipswich IP4 2FB | M10: Weekday 10am–12pm or early afternoon (between clients) | N10: Open map
A11: 10 | B11: H Beauty | C11: Beauty Salon | D11: 07778 516238 | E11: None | H11: 5 | I11: 68 | J11: Newmarket | K11: CB8 8DL | L11: 8 Rous Rd, Newmarket CB8 8DL | M11: Weekday 10am–12pm or early afternoon (between clients) | N11: Open map
A12: 11 | B12: Freyaroseaesthetics | C12: Beautician | D12: 07387 220646 | E12: None | H12: 4.9 | I12: 66 | J12: Lowestoft | K12: NR33 7NL | L12: 60 Pinbush Rd, Lowestoft NR33 7NL | M12: Weekday 10am–12pm or early afternoon (between clients) | N12: Open map
A13: 12 | B13: N&P Nails | C13: Nail Salon | D13: 07909 291140 | E13: None | H13: 4.4 | I13: 93 | J13: Bury Saint Edmunds | K13: IP33 1BJ | L13: 10 The Traverse, Bury St Edmunds, Bury Saint Edmunds IP33 1BJ | M13: Weekday 10am–12pm or early afternoon (between clients) | N13: Open map
A14: 13 | B14: Newmarket Queen's nails | C14: Nail Salon | D14: 07968 366666 | E14: Social / booking page only | F14: https://www.facebook.com/newmarket.queensnail | H14: 4.6 | I14: 113 | J14: Newmarket | K14: CB8 8EW | L14: 1 Sun Ln, Newmarket CB8 8EW | M14: Weekday 10am–12pm or early afternoon (between clients) | N14: Open map
A15: 14 | B15: REMY NAILS | C15: Nail Salon | D15: 07932 545336 | E15: None | H15: 4.1 | I15: 81 | J15: Newmarket | K15: CB8 8EE | L15: 25 Market St, Newmarket CB8 8EE | M15: Weekday 10am–12pm or early afternoon (between clients) | N15: Open map
A16: 15 | B16: Nails & Beauty | C16: Nail Salon | D16: 01473 287279 | E16: None | H16: 4 | I16: 123 | J16: Ipswich | K16: IP4 1EE | L16: 10 Upper Brook St, Ipswich IP4 1EE | M16: Weekday 10am–12pm or early afternoon (between clients) | N16: Open map
A17: 16 | B17: Goddess Nails | C17: Beauty Salon | D17: 07512 094706 | E17: None | H17: 4.9 | I17: 35 | J17: Lowestoft | K17: NR32 2AA | L17: 3 Bevan St E, Lowestoft NR32 2AA | M17: Weekday 10am–12pm or early afternoon (between clients) | N17: Open map
A18: 17 | B18: Valentines beauty 14 | C18: Beauty Salon | D18: 07861 305717 | E18: None | H18: 5 | I18: 35 | J18: Lowestoft | K18: NR32 3LD | L18: 9 Longfield Way, Oulton Broad, Lowestoft NR32 3LD | M18: Weekday 10am–12pm or early afternoon (between clients) | N18: Open map
A19: 18 | B19: NazB Beauty Studio | C19: Beauty Salon | D19: 07466 904070 | E19: None | H19: 5 | I19: 28 | J19: Newmarket | K19: CB8 8NT | L19: Fred Archer Way, Newmarket CB8 8NT | M19: Weekday 10am–12pm or early afternoon (between clients) | N19: Open map
A20: 19 | B20: Tony's Nail & Spa | C20: Nail Salon | D20: 01394 286588 | E20: None | H20: 4.5 | I20: 86 | J20: Felixstowe | K20: IP11 7AU | L20: 10 Hamilton Rd, Felixstowe IP11 7AU | M20: Weekday 10am–12pm or early afternoon (between clients) | N20: Open map
A21: 20 | B21: Luxury nails 61 | C21: Nail Salon | D21: 07859 870074 | E21: Social / booking page only | F21: https://www.facebook.com/Luxurynails61 | H21: 4.6 | I21: 84 | J21: Haverhill | K21: CB9 8AH | L21: 61c High St, Haverhill CB9 8AH | M21: Weekday 10am–12pm or early afternoon (between clients) | N21: Open map
A22: 21 | B22: Megans Beauty Boutique | C22: Beauty Salon | D22: 07534 267333 | E22: None | H22: 5 | I22: 24 | J22: Felixstowe | K22: IP11 9AA | L22: 79a High Rd W, Felixstowe IP11 9AA | M22: Weekday 10am–12pm or early afternoon (between clients) | N22: Open map
A23: 22 | B23: The Lash and Brow Studio | C23: Beauty Salon | D23: 07955 207926 | E23: None | H23: 4.7 | I23: 23 | J23: Bury Saint Edmunds | K23: IP33 3AA | L23: 102 Risbygate St, Bury St Edmunds, Bury Saint Edmunds IP33 3AA | M23: Weekday 10am–12pm or early afternoon (between clients) | N23: Open map
A24: 23 | B24: Rhiannon's Beauty Box | C24: Beauty Salon | D24: 07470 005275 | E24: None | H24: 5 | I24: 22 | J24: Sudbury | K24: CO10 9JQ | L24: KLR Beauty & Aesthetics, Cocoa-Nut House, Hall St, Long Melford, Sudbury CO10 9JQ | M24: Weekday 10am–12pm or early afternoon (between clients) | N24: Open map
A25: 24 | B25: Beauty by Abbie | C25: Beauty Salon | D25: 07854 387721 | E25: None | H25: 5 | I25: 21 | J25: Stowmarket | K25: IP14 4DT | L25: 48 Oxlip Way, Stowupland, Stowmarket IP14 4DT | M25: Weekday 10am–12pm or early afternoon (between clients) | N25: Open map
A26: 25 | B26: BOSS BEAUTY BY ADELE | C26: Beauty Salon | D26: 07504 684127 | E26: None | H26: 5 | I26: 20 | J26: Leiston | K26: IP16 4EW | L26: 20 High St, Leiston IP16 4EW | M26: Weekday 10am–12pm or early afternoon (between clients) | N26: Open map
A27: 26 | B27: @ Samantha Nicole | C27: Beauty Salon | D27: 07432 795149 | E27: None | H27: 4.8 | I27: 18 | J27: Felixstowe | K27: IP11 9JB | L27: 30 High Rd W, Felixstowe IP11 9JB | M27: Weekday 10am–12pm or early afternoon (between clients) | N27: Open map
A28: 27 | B28: Lash and Brows | C28: Beauty Salon | D28: 07777 695465 | E28: None | H28: 4.8 | I28: 18 | J28: Newmarket | K28: CB8 8EE | L28: 10b Market St, Newmarket CB8 8EE | M28: Weekday 10am–12pm or early afternoon (between clients) | N28: Open map
A29: 28 | B29: Rosie Barnes Beauty | C29: Beauty Salon | D29: 07851 915541 | E29: None | H29: 5 | I29: 18 | J29: Woodbridge | K29: IP12 1BY | L29: Orwell Fitness, East Bank House, Tide Mill Way, Woodbridge IP12 1BY | M29: Weekday 10am–12pm or early afternoon (between clients) | N29: Open map
A30: 29 | B30: Glossedbyeve | C30: Nail Salon | D30: 07415 496287 | E30: None | H30: 4.8 | I30: 17 | J30: Halesworth | K30: IP19 8AR | L30: 59b Thoroughfare, Halesworth IP19 8AR | M30: Weekday 10am–12pm or early afternoon (between clients) | N30: Open map
A31: 30 | B31: Hartfully Polished | C31: Nail Salon | D31: 07519 886080 | E31: None | H31: 5 | I31: 16 | J31: Haverhill | K31: CB9 7TH | L31: Red House, Water Ln, Barnardiston, Haverhill CB9 7TH | M31: Weekday 10am–12pm or early afternoon (between clients) | N31: Open map
A32: 31 | B32: Beautiful You | C32: Beauty Salon | D32: 07899 918631 | E32: None | H32: 5 | I32: 16 | J32: Sudbury | K32: CO10 8PH | L32: Eastfield Farm Barns, Harp Ln, Cavendish Rd, Clare, Sudbury CO10 8PH | M32: Weekday 10am–12pm or early afternoon (between clients) | N32: Open map
A33: 32 | B33: ANGEL NAILS | C33: Nail Salon | D33: 01449 541114 | E33: None | H33: 4.2 | I33: 99 | J33: Stowmarket | K33: IP14 1AD | L33: 56 Ipswich St, Stowmarket IP14 1AD | M33: Weekday 10am–12pm or early afternoon (between clients) | N33: Open map
A34: 33 | B34: Luxury Nails 142 | C34: Nail Salon | D34: 07882 299024 | E34: Social / booking page only | F34: https://www.facebook.com/profile.php?id=100086510390298 | H34: 4.8 | I34: 70 | J34: Lowestoft | K34: NR33 0AZ | L34: 142 London Rd S, Lowestoft NR33 0AZ | M34: Weekday 10am–12pm or early afternoon (between clients) | N34: Open map
A35: 34 | B35: Forever Ireland Beauty | C35: Nail Salon | D35: 07930 308258 | E35: None | H35: 4.7 | I35: 15 | J35: Bury Saint Edmunds | K35: IP28 8ZU | L35: The Mulberries, Red Lodge, Bury Saint Edmunds IP28 8ZU | M35: Weekday 10am–12pm or early afternoon (between clients) | N35: Open map
A36: 35 | B36: Just Nails | C36: Nail Salon | D36: 07539 700886 | E36: None | H36: 5 | I36: 15 | J36: Stowmarket | K36: IP14 1AD | L36: 12 Ipswich St, Stowmarket IP14 1AD | M36: Weekday 10am–12pm or early afternoon (between clients) | N36: Open map
A37: 36 | B37: The Rosie Lash | C37: Beauty Salon | D37: 07548 647627 | E37: None | H37: 5 | I37: 14 | J37: Lowestoft | K37: NR33 7BS | L37: Saxon Rd, Pakefield, Lowestoft NR33 7BS | M37: Weekday 10am–12pm or early afternoon (between clients) | N37: Open map
A38: 37 | B38: Tegan Marie Beauty | C38: Beauty Salon | D38: 07790 226936 | E38: None | H38: 5 | I38: 14 | J38: Saxmundham | K38: IP17 1WR | L38: 27 Heron Rd, Saxmundham IP17 1WR | M38: Weekday 10am–12pm or early afternoon (between clients) | N38: Open map
A39: 38 | B39: LA'NULA NAILS & Beauty | C39: Nail Salon | D39: 07772 855328 | E39: None | H39: 5 | I39: 13 | J39: Felixstowe | K39: IP11 0QL | L39: 127 Kirton Rd, Trimley St Martin, Felixstowe IP11 0QL | M39: Weekday 10am–12pm or early afternoon (between clients) | N39: Open map
A40: 39 | B40: NR Aesthetics Clinic | C40: Skin Care Clinic | D40: 07946 296853 | E40: None | H40: 5 | I40: 13 | J40: Ipswich | K40: IP7 5EH | L40: 3 Maiden Wy, Hadleigh, Ipswich IP7 5EH | M40: Weekday 10am–12pm or early afternoon (between clients) | N40: Open map
...

Sheet Builders & roofers
A1: Rank | B1: Business name | C1: Category | D1: Phone | E1: Website status | F1: Website | G1: Check first | H1: Rating | I1: Reviews | J1: Town | K1: Postcode | L1: Address | M1: Best time to call | N1: Google Maps | O1: Checked no website? (Y/N) | P1: Called (date) | Q1: Outcome | R1: Notes
A2: 1 | B2: Framlingham DIY & Building Supplies Ltd | C2: Homewares Shop | D2: 01728 723505 | E2: None | H2: 4.8 | I2: 132 | J2: Woodbridge | K2: IP13 9EA | L2: 25 Station Rd, Framlingham, Woodbridge IP13 9EA | M2: 7:30–8:30am or 5–6pm (before/after jobs) | N2: Open map
A3: 2 | B3: Belstead Roofing and maintenance services | C3: Roofing Service | D3: 07783 963033 | E3: None | H3: 4.8 | I3: 52 | J3: Ipswich | K3: IP8 3TD | L3: Holly Blue Cl, Pinewood, Ipswich IP8 3TD | M3: 7:30–8:30am or 5–6pm (before/after jobs) | N3: Open map
A4: 3 | B4: TommyBuild LTD | C4: General Contractor | D4: 07773 550843 | E4: None | H4: 5 | I4: 22 | J4: Newmarket | K4: CB8 7FX | L4: Saxon Hall Rd, Kentford, Newmarket CB8 7FX | M4: 7:30–8:30am or 5–6pm (before/after jobs) | N4: Open map
A5: 4 | B5: ELC Roofing Ltd Sudbury Suffolk | C5: Roofing Service | D5: 07956 677678 | E5: None | H5: 4.5 | I5: 16 | J5: Sudbury | K5: CO10 1WH | L5: Unit 7 Woodhall Business Park, Sudbury CO10 1WH | M5: 7:30–8:30am or 5–6pm (before/after jobs) | N5: Open map
A6: 5 | B6: A F ROBERTSON LTD - Building Contractors | C6: General Contractor | D6: 07751 223879 | E6: None | H6: 4.9 | I6: 15 | J6: Ipswich | K6: IP2 0SS | L6: London Rd, Ipswich IP2 0SS | M6: 7:30–8:30am or 5–6pm (before/after jobs) | N6: Open map
A7: 6 | B7: SJG Roofing | C7: Roofing Service | D7: 07702 873839 | E7: None | H7: 5 | I7: 14 | J7: Bury Saint Edmunds | K7: IP33 3ZB | L7: 16 Myrtle Cl, Bury St Edmunds, Bury Saint Edmunds IP33 3ZB | M7: 7:30–8:30am or 5–6pm (before/after jobs) | N7: Open map
A8: 7 | B8: TJB Carpentry & Building | C8: Manufacturer | D8: 07814 546051 | E8: None | H8: 5 | I8: 14 | J8: Sudbury | K8: CO10 2TP | L8: 15 East St, Sudbury CO10 2TP | M8: 7:30–8:30am or 5–6pm (before/after jobs) | N8: Open map
A9: 8 | B9: D Home Improvements and Roofing Services | C9: Roofing Service | D9: 07706 627575 | E9: None | H9: 4.8 | I9: 12 | J9: Haverhill | K9: CB9 0AY | L9: 10 Mildenhall Pl, Haverhill CB9 0AY | M9: 7:30–8:30am or 5–6pm (before/after jobs) | N9: Open map
A10: 9 | B10: Tgl-construction | C10: General Contractor | D10: 07376 190073 | E10: None | H10: 5 | I10: 7 | J10: Leiston | K10: IP16 4UY | L10: 23 Daisy Dr, Leiston IP16 4UY | M10: 7:30–8:30am or 5–6pm (before/after jobs) | N10: Open map
A11: 10 | B11: GDL BUILDERS | C11: Roofing Service | D11: 07979 937695 | E11: None | H11: 5 | I11: 6 | J11: Beccles | K11: NR34 7PN | L11: the apples, The St, North Cove, Beccles NR34 7PN | M11: 7:30–8:30am or 5–6pm (before/after jobs) | N11: Open map
A12: 11 | B12: BLD Construction Suffolk LTD | C12: General Contractor | D12: 07523 448761 | E12: None | H12: 5 | I12: 6 | J12: Ipswich | K12: IP2 9QX | L12: 14 Bramhall Cl, Ipswich IP2 9QX | M12: 7:30–8:30am or 5–6pm (before/after jobs) | N12: Open map
A13: 12 | B13: Home PROjects Suffolk | C13: Services | D13: 07308 233890 | E13: None | H13: 5 | I13: 6 | J13: Ipswich | K13: IP7 5AR | L13: 83 Benton St, Hadleigh, Ipswich IP7 5AR | M13: 7:30–8:30am or 5–6pm (before/after jobs) | N13: Open map
... A40: 39 | B40: Spartan Roofing | C40: Roofing Service | D40: 07599 521134 | E40: None | H40: 4.3 | I40: 6 | J40: Lowestoft | K40: NR32 2HA | L40: 66 Rotterdam Rd, Lowestoft NR32 2HA | M40: 7:30–8:30am or 5–6pm (before/after jobs) | N40: Open map
A41: 40 | B41: BHA Carpentry & Construction | C41: General Contractor | D41: 07765 651754 | E41: Social / booking page only | F41: https://www.facebook.com/BHACarpentry | H41: 5 | I41: 32 | J41: Ipswich | K41: IP5 1AS | L41: Quantock Cl, Rushmere St Andrew, Ipswich IP5 1AS | M41: 7:30–8:30am or 5–6pm (before/after jobs) | N41: Open map
A42: 41 | B42: ADT Roofing | C42: Roofing Service | D42: 01284 530067 | E42: None | H42: 5 | I42: 20 | J42: Bury | K42: IP28 8FP | L42: 43 Thistle Way, Red Lodge, Bury IP28 8FP | M42: 7:30–8:30am or 5–6pm (before/after jobs) | N42: Open map
A43: 42 | B43: Henry Abbott Hardware | C43: Hardware Shop | D43: 01728 860254 | E43: None | H43: 4.9 | I43: 20 | J43: Stowmarket | K43: IP14 6RN | L43: 1 Chancery Ln, Debenham, Stowmarket IP14 6RN | M43: 7:30–8:30am or 5–6pm (before/after jobs) | N43: Open map
A44: 43 | B44: Mildenhall Building Supplies | C44: Building materials supplier | D44: 01638 354616 | E44: None | H44: 4.9 | I44: 19 | J44: Bury Saint Edmunds | K44: IP28 7AS | L44: 25b Hampstead Ave, Mildenhall, Bury Saint Edmunds IP28 7AS | M44: 7:30–8:30am or 5–6pm (before/after jobs) | N44: Open map
A45: 44 | B45: Storford Scaffolding | D45: 07739 558630 | E45: Social / booking page only | F45: https://www.facebook.com/share/1EaqzAmNsG/?mibextid=wwXIfr | H45: 5 | I45: 14 | J45: Sudbury | K45: CO10 9SA | L45: Church St, Lavenham, Sudbury CO10 9SA | M45: 7:30–8:30am or 5–6pm (before/after jobs) | N45: Open map
A46: 45 | B46: C & C Roofing | C46: Roofing Service | D46: 01394 274119 | E46: None | H46: 4.6 | I46: 10 | J46: Felixstowe | K46: IP11 9RA | L46: 3, Hill House Cottages, Gulpher Rd, Felixstowe IP11 9RA | M46: 7:30–8:30am or 5–6pm (before/after jobs) | N46: Open map
A47: 46 | B47: McBrien Carpentry Ltd | C47: General Contractor | D47: 07887 603308 | E47: Social / booking page only | F47: https://m.facebook.com/McBrienCarpentry/ | H47: 5 | I47: 8 | J47: Haverhill | K47: CB9 9JB | L47: 41 Beech Grove, Haverhill CB9 9JB | M47: 7:30–8:30am or 5–6pm (before/after jobs) | N47: Open map
A48: 47 | B48: Brooks Joinery | C48: Services | D48: 01728 833722 | E48: None | H48: 5 | I48: 8 | J48: Leiston | K48: IP16 4JD | L48: Unit A3, Masterlord Ind. Park, Station Rd, Leiston IP16 4JD | M48: 7:30–8:30am or 5–6pm (before/after jobs) | N48: Open map
A49: 48 | B49: A & O Bow Builders | C49: General Contractor | D49: 07376 357574 | E49: Social / booking page only | F49: https://www.facebook.com/AandOBow | H49: 5 | I49: 5 | J49: Diss | K49: IP22 1HN | L49: Pottery Hill, Wattisfield, Diss IP22 1HN | M49: 7:30–8:30am or 5–6pm (before/after jobs) | N49: Open map
A50: 49 | B50: A D Burnett Roofing & Scaffolding | C50: Services | D50: 01440 706888 | E50: None | H50: 5 | I50: 4 | J50: Haverhill | K50: CB9 7SU | L50: 8 Henderson Cl, Haverhill CB9 7SU | M50: 7:30–8:30am or 5–6pm (before/after jobs) | N50: Open map
A51: 50 | B51: Downton Homes Haverhill Limited | C51: Services | D51: 01440 768668 | E51: None | H51: 5 | I51: 4 | J51: Haverhill | K51: CB9 9HG | L51: 103 Withersfield Rd, Haverhill CB9 9HG | M51: 7:30–8:30am or 5–6pm (before/after jobs) | N51: Open map
A52: 51 | B52: P. Blunden Builders | C52: Services | D52: 01502 512851 | E52: None | H52: 5 | I52: 4 | J52: Lowestoft | K52: NR32 2HD | L52: Lothing House, 7 Quay View Business Park, Barnards Way, Lowestoft NR32 2HD | M52: 7:30–8:30am or 5–6pm (before/after jobs) | N52: Open map
A53: 52 | B53: Valley Roofing IP | C53: Roofing Service | D53: 01473 567073 | E53: None | H53: 5 | I53: 3 | J53: Felixstowe | K53: IP11 7BU | L53: 40 Cowley Rd, Felixstowe IP11 7BU | M53: 7:30–8:30am or 5–6pm (before/after jobs) | N53: Open map
A54: 53 | B54: R J Kearney | C54: General Contractor | D54: 01449 722779 | E54: None | H54: 5 | I54: 3 | J54: Ipswich | K54: IP6 8DY | L54: Gipsy Ln, Needham Market, Ipswich IP6 8DY | M54: 7:30–8:30am or 5–6pm (before/after jobs) | N54: Open map
A55: 54 | B55: Suffolk Felt Roofing & Son | C55: Roofing Service | D55: 01473 726008 | E55: None | H55: 5 | I55: 3 | J55: Ipswich | K55: IP3 8SX | L55: 538 Felixstowe Rd, Ipswich IP3 8SX | M55: 7:30–8:30am or 5–6pm (before/after jobs) | N55: Open map
A56: 55 | B56: Woods outdoor creations | C56: General Contractor | D56: 07508 011513 | E56: Social / booking page only | F56: https://www.facebook.com/woods.ic | H56: 5 | I56: 3 | J56: Sudbury | K56: CO10 8NU | L56: 40 Westfield, Clare, Sudbury CO10 8NU | M56: 7:30–8:30am or 5–6pm (before/after jobs) | N56: Open map
A57: 56 | B57: M J Doubleday | C57: General Contractor | D57: 01986 896647 | E57: None | H57: 5 | I57: 2 | J57: Bungay | K57: NR35 1RL | L57: 28 Queen's Rd, Bungay NR35 1RL | M57: 7:30–8:30am or 5–6pm (before/after jobs) | N57: Open map
A58: 57 | B58: Goldcrest Construction | C58: General Contractor | D58: 01394 276696 | E58: None | H58: 4.5 | I58: 2 | J58: Felixstowe | K58: IP11 7TB | L58: 2A Valley Walk, Felixstowe IP11 7TB | M58: 7:30–8:30am or 5–6pm (before/after jobs) | N58: Open map
A59: 58 | B59: C.W.Ellis (Halesworth) Ltd | C59: Manufacturer | D59: 01986 875395 | E59: None | H59: 5 | I59: 2 | J59: Halesworth | K59: IP19 8NH | L59: Unit 2 Old Airfield, Halesworth IP19 8NH | M59: 7:30–8:30am or 5–6pm (before/after jobs) | N59: Open map
A60: 59 | B60: G Potter Builders | C60: General Contractor | D60: 07788 530510 | E60: None | H60: 2 | I60: 2 | J60: Ipswich | K60: IP5 2NX | L60: 187 Main Rd, Kesgrave, Ipswich IP5 2NX | M60: 7:30–8:30am or 5–6pm (before/after jobs) | N60: Open map
